<?xml version='1.0'?>
<robot name="car_robot">
	
	<material name="blue">
		<color rgba="0 0.4 0.5 1"/>
	</material>
	
	<!--dummy link-->
	<link name="base_link"/>
	
	<!--chassis link-->
	<link name="chassis-link">
		<visual>
			<origin xyz="0 0 0" rpy="0 0 0" />
			<geometry>
				<box size="0.2 0.12 .01" />
			</geometry>
			<material name="brown">
				<color rgba="0.3 0 0.4 1"/>
			</material>		
		</visual>
		<collision>
			<origin xyz="0 0 0" rpy="0 0 0" />
			<geometry>
				<box size="0.2 0.12 .01" />
			</geometry>
		</collision>
		<inertial>
			<mass value="0.4" />
			<inertia ixx="0.00048333" iyy="0.0013367" izz="0.0018133"
			ixy="0" ixz="0" iyz="0"/>
		</inertial>
	</link>
	
	<link name="front-right-wheel-link">
		<visual>
			<origin xyz="0 0 0" rpy="1.57079 0 0" />
			<geometry>
				<cylinder radius ="0.03"  length="0.01" />
			</geometry>
			<material name="blue" />
		</visual>
		<collision>
			<origin xyz="0 0 0" rpy="1.57079 0 0" />
			<geometry>
				<cylinder radius ="0.03"  length="0.01" />
			</geometry>
		</collision>
		<inertial>
			<origin xyz="0 0 0" rpy="1.57079 0 0" />
			<mass value="0.2" />
			<inertia ixx="0.00004667" iyy="0.00004667" izz="0.00009"
			ixy="0" ixz="0" iyz="0"/>
		</inertial>
	</link>
	
	<link name="front-left-wheel-link">
		<visual>
			<origin xyz="0 0 0" rpy="1.57079 0 0" />
			<geometry>
				<cylinder radius ="0.03"  length="0.01" />
			</geometry>
			<material name="blue" />
		</visual>
		<collision>
			<origin xyz="0 0 0" rpy="1.57079 0 0" />
			<geometry>
				<cylinder radius ="0.03"  length="0.01" />
			</geometry>
		</collision>
		<inertial>
			<origin xyz="0 0 0" rpy="1.57079 0 0" />
			<mass value="0.2" />
			<inertia ixx="0.00004667" iyy="0.00004667" izz="0.00009"
			ixy="0" ixz="0" iyz="0"/>
		</inertial>
	</link>
	
	<link name="rare-right-wheel-link">
		<visual>
			<origin xyz="0 0 0" rpy="1.57079 0 0" />
			<geometry>
				<cylinder radius ="0.03"  length="0.01" />
			</geometry>
			<material name="blue" />
		</visual>
		<collision>
			<origin xyz="0 0 0" rpy="1.57079 0 0" />
			<geometry>
				<cylinder radius ="0.03"  length="0.01" />
			</geometry>
		</collision>
		<inertial>
			<origin xyz="0 0 0" rpy="1.57079 0 0" />
			<mass value="0.2" />
			<inertia ixx="0.00004667" iyy="0.00004667" izz="0.00009"
			ixy="0" ixz="0" iyz="0"/>
		</inertial>
	</link>
	
	<link name="rare-left-wheel-link">
		<visual>
			<origin xyz="0 0 0" rpy="1.57079 0 0" />
			<geometry>
				<cylinder radius ="0.03"  length="0.01" />
			</geometry>
			<material name="blue" />
		</visual>	
		<collision>
			<origin xyz="0 0 0" rpy="1.57079 0 0" />
			<geometry>
				<cylinder radius ="0.03"  length="0.01" />
			</geometry>
		</collision>	
		<inertial>
			<origin xyz="0 0 0" rpy="1.57079 0 0" />
			<mass value="0.2" />
			<inertia ixx="0.00004667" iyy="0.00004667" izz="0.00009"
			ixy="0" ixz="0" iyz="0"/>
		</inertial>
	</link>
	
	<joint name="joint-base-chassis" type="fixed">
		<parent link="base_link"/>
		<child link="chassis-link"/>
		<origin xyz="0 0 0.03" rpy="0 0 0" />
	</joint>	
	
	<joint name="joint-chassis-front-right-wheel" type="continuous">
		<parent link="chassis-link"/>
		<child link="front-right-wheel-link"/>
		<origin xyz="0.06 0.065 0" rpy="0 0 0" />
		<axis xyz="0 1 0" />
	</joint>
	
	<joint name="joint-chassis-front-left-wheel" type="continuous">
		<parent link="chassis-link"/>
		<child link="front-left-wheel-link"/>
		<origin xyz="0.06 -0.065 0" rpy="0 0 0" />
		<axis xyz="0 1 0" />
	</joint>
	
	<joint name="joint-chassis-rare-right-wheel" type="continuous">
		<parent link="chassis-link"/>
		<child link="rare-right-wheel-link"/>
		<origin xyz="-0.06 0.065 0" rpy="0 0 0" />
		<axis xyz="0 1 0" />
	</joint>
	
	<joint name="joint-chassis-rare-left-wheel" type="continuous">
		<parent link="chassis-link"/>
		<child link="rare-left-wheel-link"/>
		<origin xyz="-0.06 -0.065 0" rpy="0 0 0" />
		<axis xyz="0 1 0" />
	</joint>
	
	
</robot>
