<?xml version="1.0" ?>
<!-- =================================================================================== -->
<!-- |    This document was autogenerated by xacro from car-robot.xacro                | -->
<!-- |    EDITING THIS FILE BY HAND IS NOT RECOMMENDED                                 | -->
<!-- =================================================================================== -->
<robot name="car-robot">
  <!--dummy link-->
  <link name="base_link"/>
  <!--chassis link-->
  <link name="chassis-link">
    <visual>
      <origin rpy="0 0 0" xyz="0 0 0"/>
      <geometry>
        <box size="0.14 0.12 0.01"/>
      </geometry>
      <material name="brown">
        <color rgba="0.3 0 0.4 1"/>
      </material>
    </visual>
    <collision>
      <origin rpy="0 0 0" xyz="0 0 0"/>
      <geometry>
        <box size="0.14 0.12 0.01"/>
      </geometry>
    </collision>
    <inertial>
      <mass value="0.4"/>
      <inertia ixx="0.00048333" ixy="0" ixz="0" iyy="0.0013367" iyz="0" izz="0.0018133"/>
    </inertial>
  </link>
  <joint name="joint-base-chassis" type="fixed">
    <parent link="base_link"/>
    <child link="chassis-link"/>
    <origin rpy="0 0 0" xyz="0 0 0.02"/>
  </joint>
  <material name="blue">
    <color rgba="0 0.4 0.5 1"/>
  </material>
  <!-- ${x_position}-${y_position}-wheel-link -->
  <link name="front-right-wheel-link">
    <visual>
      <origin rpy="1.5707963267948966 0 0" xyz="0 0 0"/>
      <geometry>
        <cylinder length="0.01" radius="0.02"/>
      </geometry>
      <material name="blue"/>
    </visual>
    <collision>
      <origin rpy="1.5707963267948966 0 0" xyz="0 0 0"/>
      <geometry>
        <cylinder length="0.01" radius="0.02"/>
      </geometry>
    </collision>
    <inertial>
      <origin rpy="1.5707963267948966 0 0" xyz="0 0 0"/>
      <mass value="0.2"/>
      <inertia ixx="2.166666666666667e-05" ixy="0" ixz="0" iyy="2.166666666666667e-05" iyz="0" izz="4e-05"/>
    </inertial>
  </link>
  <joint name="joint-chassis-front-right-wheel" type="continuous">
    <parent link="chassis-link"/>
    <child link="front-right-wheel-link"/>
    <origin rpy="0 0 0" xyz="0.042 0.065 0"/>
    <axis xyz="0 1 0"/>
  </joint>
  <!-- ${x_position}-${y_position}-wheel-link -->
  <link name="front-left-wheel-link">
    <visual>
      <origin rpy="1.5707963267948966 0 0" xyz="0 0 0"/>
      <geometry>
        <cylinder length="0.01" radius="0.02"/>
      </geometry>
      <material name="blue"/>
    </visual>
    <collision>
      <origin rpy="1.5707963267948966 0 0" xyz="0 0 0"/>
      <geometry>
        <cylinder length="0.01" radius="0.02"/>
      </geometry>
    </collision>
    <inertial>
      <origin rpy="1.5707963267948966 0 0" xyz="0 0 0"/>
      <mass value="0.2"/>
      <inertia ixx="2.166666666666667e-05" ixy="0" ixz="0" iyy="2.166666666666667e-05" iyz="0" izz="4e-05"/>
    </inertial>
  </link>
  <joint name="joint-chassis-front-left-wheel" type="continuous">
    <parent link="chassis-link"/>
    <child link="front-left-wheel-link"/>
    <origin rpy="0 0 0" xyz="0.042 -0.065 0"/>
    <axis xyz="0 1 0"/>
  </joint>
  <!-- ${x_position}-${y_position}-wheel-link -->
  <link name="rare-right-wheel-link">
    <visual>
      <origin rpy="1.5707963267948966 0 0" xyz="0 0 0"/>
      <geometry>
        <cylinder length="0.01" radius="0.02"/>
      </geometry>
      <material name="blue"/>
    </visual>
    <collision>
      <origin rpy="1.5707963267948966 0 0" xyz="0 0 0"/>
      <geometry>
        <cylinder length="0.01" radius="0.02"/>
      </geometry>
    </collision>
    <inertial>
      <origin rpy="1.5707963267948966 0 0" xyz="0 0 0"/>
      <mass value="0.2"/>
      <inertia ixx="2.166666666666667e-05" ixy="0" ixz="0" iyy="2.166666666666667e-05" iyz="0" izz="4e-05"/>
    </inertial>
  </link>
  <joint name="joint-chassis-rare-right-wheel" type="continuous">
    <parent link="chassis-link"/>
    <child link="rare-right-wheel-link"/>
    <origin rpy="0 0 0" xyz="-0.042 0.065 0"/>
    <axis xyz="0 1 0"/>
  </joint>
  <!-- ${x_position}-${y_position}-wheel-link -->
  <link name="rare-left-wheel-link">
    <visual>
      <origin rpy="1.5707963267948966 0 0" xyz="0 0 0"/>
      <geometry>
        <cylinder length="0.01" radius="0.02"/>
      </geometry>
      <material name="blue"/>
    </visual>
    <collision>
      <origin rpy="1.5707963267948966 0 0" xyz="0 0 0"/>
      <geometry>
        <cylinder length="0.01" radius="0.02"/>
      </geometry>
    </collision>
    <inertial>
      <origin rpy="1.5707963267948966 0 0" xyz="0 0 0"/>
      <mass value="0.2"/>
      <inertia ixx="2.166666666666667e-05" ixy="0" ixz="0" iyy="2.166666666666667e-05" iyz="0" izz="4e-05"/>
    </inertial>
  </link>
  <joint name="joint-chassis-rare-left-wheel" type="continuous">
    <parent link="chassis-link"/>
    <child link="rare-left-wheel-link"/>
    <origin rpy="0 0 0" xyz="-0.042 -0.065 0"/>
    <axis xyz="0 1 0"/>
  </joint>
  <gazebo reference="chassis-link">
    <material>Gazebo/DarkGrey</material>
  </gazebo>
  <gazebo>
    <!-- differential drive control for Gazebo -->
    <plugin filename="libgazebo_ros_diff_drive.so" name="differential_drive_controller">
      <alwaysOn>true</alwaysOn>
      <updateRate>100</updateRate>
      <leftJoint>joint-chassis-rare-left-wheel</leftJoint>
      <rightJoint>joint-chassis-rare-right-wheel</rightJoint>
      <wheelSeparation>0.12</wheelSeparation>
      <wheelDiameter>0.04</wheelDiameter>
      <torque>0.1</torque>
      <commandTopic>cmd_vel</commandTopic>
      <odometryTopic>odom</odometryTopic>
      <odometryFrame>odom</odometryFrame>
      <robotBaseFrame>base_link</robotBaseFrame>
      <publishWheelTF>true</publishWheelTF>
      <publishOdom>true</publishOdom>
      <publishWheelJointState>true</publishWheelJointState>
    </plugin>
  </gazebo>
  <gazebo reference="front-right-wheel-link">
    <mu1>10000.0 </mu1>
    <mu2>10000.0 </mu2>
    <material>Gazebo/Purple</material>
  </gazebo>
  <gazebo reference="front-left-wheel-link">
    <mu1>10000.0 </mu1>
    <mu2>10000.0 </mu2>
    <material>Gazebo/Purple</material>
  </gazebo>
  <gazebo reference="rare-right-wheel-link">
    <mu1>10000.0 </mu1>
    <mu2>10000.0 </mu2>
    <material>Gazebo/Purple</material>
  </gazebo>
  <gazebo reference="rare-left-wheel-link">
    <mu1>10000.0 </mu1>
    <mu2>10000.0 </mu2>
    <material>Gazebo/Purple</material>
  </gazebo>
</robot>

